Workbook

Sheet Расписание
A1: 1А | B1: Тьютор Коновалова Евгения
A2: Время | B2: Понедельник | C2: Вторник | D2: Среда | E2: Четверг | F2: Пятница
A3: 8.45-9.00 | B3: Сонастройка Коновалова | C3: Сонастройка Пашкова | D3: Сонастройка Коновалова | E3: Сонастройка Коновалова | F3: Сонастройка Пашкова
A4: 9.00-9.45 | B4: Русский язык Пашкова | C4: Математика Савина | D4: Русский язык Пашкова | E4: тьюторский час Коновалова | F4: Технология Бондарь
A5: 9.55-10.40 | B5: Окружающий мир Савина | C5: Литературное чтение Пашкова | D5: Математика Савина | E5: Окружающий мир Савина | F5: Математика Савина
A6: 10.50-11.35 | B6: Музыка Карпова | E6: Литературное чтение Пашкова
A7: 11.35-15.00 | B7: ОБЕД
A8: 15.00-16.00 | B8: Продленка групповая Юманова Дарья
A9: 16.00-17.00 | B9: Творческая мастерская (Коновалова Евгения) | C9: Творческая мастерская (Коновалова Евгения) | D9: Творческая мастерская (Коновалова Евгения)
A11: 1Б | B11: Тьютор Рассолова Екатерина
A12: Время | B12: Понедельник | C12: Вторник | D12: Среда | E12: Четверг | F12: Пятница
A13: 11.30-11.45 | B13: Сонастройка Коновалова | C13: Сонастройка Савина | D13: Сонастройка Коновалова | E13: Сонастройка Савина | F13: Сонастройка Коновалова
A14: 11.45-12.30 | B14: Окружающий мир Савина | C14: Математика Савина | D14: Математика Савина | E14: Русский язык Пашкова | F14: Математика Савина
A15: 12.40-13.25 | B15: Технология Бондарь | C15: Русский язык Пашкова | D15: Литературное чтение Пашкова | E15: Окружающий мир Савина | F15: Литературное чтение Пашкова
A16: 13.35 -14.20 | B16: Музыка Карпова | D16: Тьюторский час Рассолова
A17: 14.20-15.00 | B17: ОБЕД
A18: 15.00-16.00 | B18: Продленка групповая Юманова Дарья
A19: 16.00-17.00 | B19: Творческая мастерская (Рассолова Екатерина) | C19: Творческая мастерская (Рассолова Екатерина) | D19: Творческая мастерская (Рассолова Екатерина)
A21: 2А | B21: Тьютор Силосьева Алла
A22: Время | B22: Понедельник | C22: Вторник | D22: Среда | E22: Четверг | F22: Пятница
A23: 8.45-9.00 | B23: Сонастройка Козлова | C23: Сонастройка Козлова | D23: Сонастройка Козлова | E23: Сонастройка Силосьева Алла | F23: Сонастройка Козлова
A24: 9.00-9.45 | B24: Русский язык Козлова | C24: Технология Бондарь | D24: Русский язык Козлова | E24: Литература Козлова | F24: Литература Козлова
A25: 9.55-10.40 | B25: Музыка Карпова | C25: Русский язык Козлова | D25: Окружающий мир Пашкова | E25: Окружающий мир Пашкова | F25: Английский язык Ерохина
A26: 10.50-11.35 | B26: Английский язык Ерохина | C26: Математика Пашкова | D26: Английский язык Ерохина | E26: Тьюторский час Силосьева | F26: Математика Пашкова
A27: 11.45-12.30 | B27: Математика Пашкова
A28: 12.30-15.00 | B28: ОБЕД
A29: 15.00-16.00 | B29: Продленка Коновалова Евгения
A30: 16.00-17.00 | B30: Творческая мастерская (Силосьева Алла) | C30: Творческая мастерская (Цуркан Юлия) | D30: Творческая мастерская (Аношко Лиана)
A32: 2Б | B32: Тьютор Рассолова Екатерина
A33: Время | B33: Понедельник | C33: Вторник | D33: Среда | E33: Четверг | F33: Пятница
A34: 11.30-11.45 | B34: Сонастройка | C34: Сонастройка Ерохина | D34: Сонастройка Козлова Галина | E34: Сонастройка Козлова | F34: Сонастройка Козлова Галина
A35: 11.45-12.30 | B35: Русский язык Козлова | C35: Английский язык Ерохина | D35: Русский язык Козлова | E35: Литература Козлова | F35: Технология Бондарь
A36: 12.40-13.25 | B36: Окружающий мир Савина | C36: Математика Савина | D36: Математика Савина | E36: Английский язык Ерохина | F36: Математика Савина
A37: 13.35-14.20 | B37: тьюторский час Коновалова | C37: Литература Козлова | D37: Английский язык Ерохина | E37: Окружающий мир Савина | F37: Русский язык Козлова
A38: 14.30-15.15 | B38: Музыка Карпова
A39: 14.20- 15.00 | B39: ОБЕД
A40: 15.00-16.00 | C40: Продленка Коновалова Евгения
A41: 16.00-17.00 | B41: Творческая мастерская (Силосьева Алла) | C41: Творческая мастерская (Цуркан Юлия) | D41: Творческая мастерская (Аношко Лиана)
A43: 2В | B43: Тьютор Рассолова Екатерина
A44: Время | B44: Понедельник | C44: Вторник | D44: Среда | E44: Четверг | F44: Пятница
...

Sheet Расписание для родителей
A1: 1А
A2: Время | B2: Понедельник | C2: Вторник | D2: Среда | E2: Четверг | F2: Пятница
A3: 8.45-9.00 | B3: Сонастройка | C3: Сонастройка | D3: Сонастройка | E3: Сонастройка | F3: Сонастройка
A4: 9.00-9.45 | B4: Русский язык | C4: Математика | D4: Русский язык | E4: Тьюторский час | F4: Технология
A5: 9.55-10.40 | B5: Окружающий мир | C5: Литературное чтение | D5: Математика | E5: Окружающий мир | F5: Математика
A6: 10.50-11.35 | B6: Музыка | E6: Литературное чтение
A7: 11.35-15.00 | B7: ОБЕД
A8: 15.00-16.00 | B8: Продленка
A9: 16.00-17.00 | B9: Творческая мастерская | C9: Творческая мастерская | D9: Творческая мастерская
A11: 1Б
A12: Время | B12: Понедельник | C12: Вторник | D12: Среда | E12: Четверг | F12: Пятница
A13: 11.30-11.45 | B13: Сонастройка | C13: Сонастройка | D13: Сонастройка | E13: Сонастройка | F13: Сонастройка
A14: 11.45-12.30 | B14: Окружающий мир | C14: Математика | D14: Математика | E14: Русский язык | F14: Математика
A15: 12.40-13.25 | B15: Технология | C15: Русский язык | D15: Литературное чтение | E15: Окружающий мир | F15: Литературное чтение
A16: 13.35 -14.20 | B16: Музыка | D16: Тьюторский час
A17: 14.20-15.00 | B17: ОБЕД
A18: 15.00-16.00 | B18: Продленка
A19: 16.00-17.00 | B19: Творческая мастерская | C19: Творческая мастерская | D19: Творческая мастерская
A21: 2А
A22: Время | B22: Понедельник | C22: Вторник | D22: Среда | E22: Четверг | F22: Пятница
A23: 8.45-9.00 | B23: Сонастройка | C23: Сонастройка | D23: Сонастройка | E23: Сонастройка | F23: Сонастройка
A24: 9.00-9.45 | B24: Русский язык | C24: Технология | D24: Русский язык | E24: Литература | F24: Литература
A25: 9.55-10.40 | B25: Музыка | C25: Русский язык | D25: Окружающий мир | E25: Окружающий мир | F25: Английский язык
A26: 10.50-11.35 | B26: Английский язык | C26: Математика | D26: Английский язык | E26: Тьюторский час | F26: Математика
A27: 11.45-12.30 | B27: Математика
A28: 11.45/12.30- 15.00 | B28: ОБЕД
A29: 15.00-16.00 | B29: Продленка
A30: 16.00-17.00 | B30: Творческая мастерская | C30: Творческая мастерская | D30: Творческая мастерская
A32: 2Б
A33: Время | B33: Понедельник | C33: Вторник | D33: Среда | E33: Четверг | F33: Пятница
A34: 11.30-11.45 | B34: Сонастройка | C34: Сонастройка | D34: Сонастройка | E34: Сонастройка | F34: Сонастройка
A35: 11.45-12.30 | B35: Русский язык | C35: Английский язык | D35: Русский язык | E35: Литература | F35: Технология
A36: 12.40-13.25 | B36: Окружающий мир | C36: Математика | D36: Математика | E36: Английский язык | F36: Математика
A37: 13.35-14.20 | B37: Тьюторский час | C37: Литература | D37: Английский язык | E37: Окружающий мир | F37: Русский язык
A38: 14.30-15.15 | B38: Музыка
A39: 14.20/15.15- 15.00/16.00 | B39: ОБЕД
A40: 15.00-16.00 | B40: Продленка | D40: Продленка | E40: Продленка | F40: Продленка
A41: 16.00-17.00 | B41: Творческая мастерская | C41: Творческая мастерская | D41: Творческая мастерская
A43: 2В
A44: Время | B44: Понедельник | C44: Вторник | D44: Среда | E44: Четверг | F44: Пятница
...

Sheet Расписание тьюторы
J1: Расписание уроков ЭИ
B2: Алла Силосьева / 2а, 3а, 5а | J2: Урок | L2: Понедельник | M2: Вторник | N2: Среда | O2: Четверг | P2: Пятница
C3: Понедельник | D3: Вторник | E3: Среда | F3: Четверг | G3: Пятница | J3: 1 | K3: 9.00–9.45/ 9.00-9.30 | L3: Тьюторский час 4А (Цуркан) | M3: Тьюторский час 4В (Цуркан) | O3: Тьюторский час 7Б (Лалетина)
A4: Урок | B4: Сонастройка 8.45 - 9.00 | C4: 2а | D4: 3а | E4: 5а | F4: 2а | G4: 3а | H4: в среду стоял 2а, теперь 5А | J4: 2 | K4: 9.55–10.40/ 9.45-10.15 | N4: Тьюторский час 5А (Силосьева)
A5: 1 | B5: 9.00–9.45 | F5: Тьюторский час 3А | N5: Тьюторский час 9А (Лалетина)
A6: 2 | B6: 9.55–10.40 | E6: Тьюторский час 5А | J6: 3 | K6: 10.50–11.35/ 10.30-11.00 | L6: Тьюторский час 6Б (Голубева) | M6: Тьюторский час 1А (Рассолова) | N6: Тьюторский час 6А (Голубева) | P6: Тьюторский час 2А (Силосьева)
A7: 3 | B7: 10.50–11.35 | G7: Тьюторский час 2А | P7: Тьюторский час 3В (Аношко)
A8: 4 | B8: 11.45–12.30 | J8: 4 | K8: 11.45–12.30/ 11.45-12.15 | L8: Тьюторский час 3Б (Аношко) | M8: Тьюторский час 5Б (Лукина) | P8: Тьюторский час 2Б (Рассолова)
A9: 5 | B9: 12.40–13.25 | O9: Тьюторский час 3А (Силосьева)
A10: 6 | B10: 13.35–14.20 | J10: 5 | K10: 12.40–13.25/ 12.30-13.00 | M10: Тьюторский час 5В (Лукина) | P10: Тьюторский час 8А (Лалетина)
A11: 7 | B11: 14.30–15.15 | J11: 6 | K11: 13.35–14.20/ 13.15-13.45 | N11: Тьюторский час 1Б (Рассолова)
A12: 8 | B12: 15.00 - 16.00 | J12: 7 | K12: 14.30–15.15 | N12: Тьюторский час 7А (Лалетина) | P12: Тьюторский час 4Б (Цуркан)
A13: 9 | B13: 16.00 - 17.00 | C13: Творческая мастерская (1А, 1Б, 2А) | D13: Творческая мастеркая (3а, 3в, 4а, 4в)
B18: Рассолова Екатерина / 1а, 1б, 2б, 2в
C19: Понедельник | D19: Вторник | E19: Среда | F19: Четверг | G19: Пятница
A20: Урок | B20: Сонастройка 8.45 - 9.00 | C20: 1А | D20: 1А | E20: 1А | F20: 1А | G20: 1А
A21: 1 | B21: 9.00–9.30
A22: 2 | B22: 9.45–10.15
A23: 3 | B23: 10.30-11.00 | D23: Тьюторский час 1А
B24: Сонастройка 11.30-11.45 | C24: 2Б | D24: 1Б | E24: 2Б | F24: 1Б | G24: 2Б
A25: 4 | B25: 11.45–12.30/ 11.45-12.15 | G25: Тьюторский час 2В
A26: 5 | B26: 12.40–13.25/ 12.30-13.00
A27: 6 | B27: 13.35–14.20/ 13.15-13.45 | C27: Тьюторский час 2Б | E27: Тьюторский час 1Б
A28: 7 | B28: 14.30–15.15
B29: 15.00-16.00 | C29: Продленка (1а, 1б)
A30: 8 | B30: 16.00-17.00 | D30: Творческая мастерская (1А, 1Б)
A32: Лиана Аношко / 3б, 3в
C33: Понедельник | D33: Вторник | E33: Среда | F33: Четверг | G33: Пятница
A34: Урок | B34: Сонастройка 8.45 - 9.00 | C34: 3В | D34: 3В | E34: 3В | F34: 3В | G34: 3В
A35: 1 | B35: 9.00–9.45
A36: 2 | B36: 9.55–10.40 | C36: Тьюторский час 3В
A37: 3 | B37: 10.50–11.35
B38: Сонастройка 11.30-11.45 | C38: 3Б | D38: 3Б | E38: 3Б | F38: 3Б | G38: 3Б
A39: 4 | B39: 11.45–12.30 | C39: Тьюторский час 3Б
A40: 5 | B40: 12.40–13.25
A41: 6 | B41: 13.35–14.20
A42: 7 | B42: 14.00-15.00
A43: 8 | B43: 15.00 - 16.00 | C43: Продленка (3а, 3б, 3в)
A44: 9 | B44: 16.00-17.00 | C44: Творческая мастерская (2Б, 3Б, 4Б) | E44: Творческая мастерская (2Б, 3Б, 4Б)
A46: Голубева Елизавета / 6а, 6б
...

Sheet Расписание по педагогам
A1: Расписание: Бондарь Ольга (ИЗО/технология) Количество часов:11 | F1: 11 | H1: согласовано
A3: Урок | B3: Время | C3: Понедельник | D3: Вторник | E3: Среда | F3: Четверг | G3: Пятница
A4: 1 | B4: 9.00–9.45 | D4: 2А | E4: 4В | F4: 2В | G4: 1А
A5: 2 | B5: 9.55–10.40 | G5: 4А
A6: 3 | B6: 10.50–11.35 | G6: 3А
A7: 4 | B7: 11.45–12.30 | C7: 4Б | D7: 3В | G7: 2Б
A8: 5 | B8: 12.40–13.25 | C8: 1Б | D8: 3Б
A9: 6 | B9: 13.35–14.20
A10: 7 | B10: 14.30–15.15
A11: 8
A12: 101
A13: 102
I14: старое расписание | Q14: старое расписание
A15: Расписание: Ерохина Анастасия (Английский язык) Количество часов: 15 | H15: согласовано | I15: Расписание: Ерохина Анастасия (Английский язык) Количество часов: 15 | Q15: Расписание: Ерохина Анастасия (Английский язык) Количество часов: 15
A17: Урок | B17: Время | C17: Понедельник | D17: Вторник | E17: Среда | F17: Четверг | G17: Пятница | I17: Урок | J17: Время | K17: Понедельник | L17: Вторник | M17: Среда | N17: Четверг | O17: Пятница | Q17: Урок | R17: Время | S17: Понедельник | T17: Вторник | U17: Среда | V17: Четверг | W17: Пятница
A18: 1 | B18: 9.00–9.45 | I18: 1 | J18: 9.00–9.45 | Q18: 1 | R18: 9.00–9.45
A19: 2 | B19: 9.55–10.40 | C19: 3А | E19: 3В | F19: 3В | G19: 2А | I19: 2 | J19: 9.55–10.40 | K19: 3В | L19: 3А | M19: 3В | N19: 3В | O19: 2А | Q19: 2 | R19: 9.55–10.40 | S19: 3А | U19: 3В | V19: 3В | W19: 2А
A20: 3 | B20: 10.50–11.35 | C20: 2А | E20: 2А | F20: 3А | G20: 3В | I20: 3 | J20: 10.50–11.35 | K20: 3А | M20: 2А | N20: 3А | Q20: 3 | R20: 10.50–11.35 | U20: 2А | V20: 3А | W20: 3В
B21: 11.30-11.45 | D21: сонастройка | J21: 11.30-11.45 | L21: сонастройка | R21: 11.30-11.45 | T21: сонастройка
A22: 4 | B22: 11.45–12.30 | D22: 2Б | E22: 3Б | G22: 3А | I22: 4 | J22: 11.45–12.30 | K22: 2А | L22: 2Б | M22: 3Б | Q22: 4 | R22: 11.45–12.30 | S22: 2А | T22: 2Б | U22: 3Б | W22: 3А
A23: 5 | B23: 12.40–13.25 | F23: 2Б | G23: 3Б | I23: 5 | J23: 12.40–13.25 | N23: 2Б | O23: 3Б | Q23: 5 | R23: 12.40–13.25 | V23: 2Б | W23: 3Б
A24: 6 | B24: 13.35–14.20 | E24: 2Б | F24: 3Б | I24: 6 | J24: 13.35–14.20 | M24: 2Б | N24: 3Б | Q24: 6 | R24: 13.35–14.20 | U24: 2Б | V24: 3Б
A25: 7 | B25: 14.30–15.15 | I25: 7 | J25: 14.30–15.15 | Q25: 7 | R25: 14.30–15.15
A26: 8 | I26: 8 | Q26: 8
A27: 101 | I27: 101 | Q27: 101
A28: 102 | I28: 102 | Q28: 102
A30: Расписание: Малкова Полина (Английский язык) Количество часов: 12 | I30: Расписание: Малкова Полина (Английский язык) Количество часов: 12
A32: Урок | B32: Время | C32: Понедельник | D32: Вторник | E32: Среда | F32: Четверг | G32: Пятница | I32: Урок | J32: Время | K32: Понедельник | L32: Вторник | M32: Среда | N32: Четверг | O32: Пятница
B33: 8.45-9.00 | C33: сонастройка | J33: 8.45-9.00 | K33: сонастройка
A34: 1 | B34: 9.00–9.45 | C34: 4В | E34: 4А | F34: 4А | G34: 4А | I34: 1 | J34: 9.00–9.45 | K34: 4В | M34: 4А | N34: 4А | O34: 4А
A35: 2 | B35: 9.55–10.40 | C35: 2В | E35: 2В | F35: 2В | G35: 4В | I35: 2 | J35: 9.55–10.40 | K35: 2В | M35: 2В | N35: 2В | O35: 4В
A36: 3 | B36: 10.50–11.35 | F36: 4В | I36: 3 | J36: 10.50–11.35 | N36: 4В
A37: 4 | B37: 11.45–12.30 | I37: 4 | J37: 11.45–12.30 | N37: 4Б
A38: 5 | B38: 12.40–13.25 | F38: 4Б | G38: 4Б | I38: 5 | J38: 12.40–13.25 | O38: 4Б
A39: 6 | B39: 13.35–14.20 | E39: 4Б | I39: 6 | J39: 13.35–14.20 | M39: 4Б
A40: 7 | B40: 14.30–15.15 | I40: 7 | J40: 14.30–15.15
A41: 8 | I41: 8
A42: 101 | I42: 101
A43: 102 | I43: 102
A45: Расписание: Матвеева Валерия (Английский язык) Количество часов: 9
...

Sheet Лист33
A1: Расписание: Ларшина Анастасия (Алгебра, Геометрия, Информатика) Количество часов: 19 | I1: Расписание: Ларшина Анастасия (Алгебра, Геометрия, Информатика) Количество часов: 19
A3: Урок | B3: Время | C3: Понедельник | D3: Вторник | E3: Среда | F3: Четверг | G3: Пятница | I3: Урок | J3: Время | K3: Понедельник | L3: Вторник | M3: Среда | N3: Четверг | O3: Пятница
D4: сонастройка | F4: сонастройка | K4: сонастройка | L4: сонастройка | N4: сонастройка | O4: сонастройка
A5: 1 | B5: 9.00–9.45 | C5: 8А | D5: 8А | E5: 9А | F5: 8А | G5: 9А | I5: 1 | J5: 9.00–9.45 | K5: 7Б (алгебра) | L5: 8А | M5: 9А | N5: 8А | O5: 7Б (геометрия)
A6: 2 | B6: 9.55–10.40 | C6: 8А | D6: 9А | E6: 9А | F6: 9А | G6: 8А | I6: 2 | J6: 9.55–10.40 | K6: 8А | L6: 9А | M6: 9А | N6: 9А | O6: 8А
A7: 3 | B7: 10.50–11.35 | C7: 9А | D7: 7Б (алгебра) | E7: 8А | F7: 7Б (алгебра) | G7: 7Б (геометрия) | I7: 3 | J7: 10.50–11.35 | K7: 9А | M7: 8А | N7: 7Б (алгебра) | O7: 8А (инф)
A8: 4 | B8: 11.45–12.30 | C8: 7Б | D8: 7А | E8: 7Б (геометрия) | F8: 7Б (алгебра) | I8: 4 | J8: 11.45–12.30 | K8: 7Б | L8: 7А | M8: 7Б (геометрия) | N8: 7Б (геометрия) | O8: 9А
A9: 5 | B9: 12.40–13.25 | D9: 7А | G9: 7А | I9: 5 | J9: 12.40–13.25 | L9: 7А | O9: 7А
A10: 6 | B10: 13.35–14.20 | G10: 7А | I10: 6 | J10: 13.35–14.20 | O10: 7А
A11: 7 | B11: 14.30–15.15 | F11: 7А | I11: 7 | J11: 14.30–15.15 | N11: 7А
A12: 8 | C12: 7А | I12: 8 | K12: 7А
A13: 101 | I13: 101
A14: 102 | I14: 102
A16: Расписание: Карнаушенко Оксана (Математика) Количество часов: 11
A18: Урок | B18: Время | C18: Понедельник | D18: Вторник | E18: Среда | F18: Четверг | G18: Пятница
B19: 8.45 -9.00 | C19: сонастройка | E19: сонастройка | G19: сонастройка
A20: 1 | B20: 9.00–9.45
A21: 2 | B21: 9.55–10.40 | E21: 6Б | F21: 6Б
A22: 3 | B22: 10.50–11.35 | C22: 6А | D22: 6А | F22: 6А
A23: 4 | B23: 11.45–12.30 | D23: 6Б
A24: 5 | B24: 12.40–13.25
A25: 6 | B25: 13.35–14.20
A26: 7 | B26: 14.30–15.15
A27: 8
A28: 101
A29: 102

Sheet ОГЭЕГЭ
A1: Педагог | B1: Предмет | C1: Слоты | D1: Ставка педагога | E1: Комментарий
A2: Латышева Ирина | B2: английский язык | C2: пн - 12.40 - 16.30 вт - 12.40 - 13.30 ср - 9.00 - 13.00 чт - 10.00 - 12.30 пт - 12.00 - 13.00 / 14.30 - 15.15 | D2: у нее урок стоит 1500 р. | E2: Только ОГЭ
A3: Мишина Валерия | B3: русский язык и литература | E3: думает до 5.02, интересно предложение
A4: Вайнула Анастасия | B4: русский язык и литература | E4: сейчас увеличилась нагрузка за счет 8а, 9.02 даст ответ
A5: Ларшина Анастасия | B5: алгебра, геометрия, информатика | E5: жду слоты, обещала сегодня после занятий скинуть
A6: Гайденко Елена | B6: география | C6: Понедельник: 15.00, 19.00, 20.00 Вторник: 15.00 (инд.Фисюк Артем - если сдвинем на 14.00 - можно освободить), 19.00, 20.00. Среда: 16.00, 20.00, скоро освободится и 15.00 Четверг: 15.00 (1 раз в месяц Ульяна Гавриш - если сдвинем на 14.00 - можно освободить), 20.00. Пятница: 15.00, 19.00, 20.00. Суббота: 9.00, 10.00, 11.00, 12.00 | D6: 800р - мини-группа, 1200р - инд | E6: ОГЭ/ЕГЭ
A7: Коломеец Екатерина | B7: обществознание | C7: Понедельник: 15:00 - 15:45, 16:00 - 16:45; Вторник 17:00 - 17:45 Среда: 15:00 - 15:45, 16:00 - 16:45; Четверг: 17:00 - 17:45; 18:00 - 18:45 Пятница: 14:00-14:45; 15:00 - 15:45, 16:00 - 16:45; | D7: Мини-группа - 800 рублей Инд. занятие - 1000 рублей | E7: ОГЭ/ЕГЭ
A8: Смирнова Вероника | B8: русский язык и литература | C8: - понедельник: 14:00; 15:00; 18:00 - четверг: 15:00; 16:00; 19:00 - пятница: 15:00; 17:00 | D8: 800 р | E8: ОГЭ/ЕГЭ Только индивидуалы
A9: Баранникова Лада | B9: химия | C9: Пн 19.00-22.00 Вт 19.00-22.00 Пт 17.00-22.00 Сб 17.00-22.00 Вс 17.00-22.00 | D9: 800 р | E9: ОГЭ/ЕГЭ Только индивидуалы
A10: Матвеева Валерия | B10: английский язык | C10: 1. Вторник: с 15:00 до 18:00. 2. Среда: 14:30 - 15:30. 3. Четверг: с 15:00 до 18:00 4. Пятница: с 14:30 до 15:30, с 16:30 до 17:30 5.В субботу: - с 9:00 до 11:00; - с 13:00 до 14:00 - с 15:00 до 16:00 | E10: Только ОГЭ Только индивидуалы
A11: Помещикова Мария | B11: история | E11: На данный момент на март у меня нет лимита, так как я еще не распределила туда нагрузку
A12: Потенциал
A13: Созонов Никита | B13: химия
A14: Виноградова | B14: математика
A15: Холкин | B15: физика

Sheet Нагрузка педагогов
A1: Педагог | B1: Нагрузка классы | C1: Нагрузка инди | D1: Всего
A2: Бондарь Ольга | B2: 11 | D2: 11
A3: Ерохина Анастасия | B3: 15 | D3: 15 | E3: помощник
A4: Дутова Анна | B4: 0 | C4: 6 | D4: =SUM(B4:C4) -> 6
A5: Зиновьева Александра | B5: 12 | C5: 2 | D5: 14
A6: Латышева Ирина | B6: 6 | C6: 1 | D6: 7 | E6: Калинина
A7: Козлова Галина | B7: 20 | D7: 20
A8: Чеченкова Светлана | B8: 15 | D8: 15
A9: Конохов Павел | B9: 13 | D9: 13
A10: Савина Ксения | B10: 25 | D10: 25
A11: Петрова Елизавета | B11: 15 | D11: 15
A12: Карабанова Маргарита | B12: 11 | D12: 11
A13: Тенешева Дарья | B13: 11 | D13: 11
A14: Мишина Валерия | B14: 15 | D14: 15
A15: Вайнула Анастасия | B15: 20 | D15: 20
A16: Ларшина Анастасия | B16: 19 | D16: 19
A17: Михайлова Марина | B17: 9 | D17: 9
A18: Карнаушенко Оксана | B18: 11 | D18: 11
A19: Павленко Ольга | B19: 10.5 | C19: 1 | D19: =SUM(B19:C19) -> 11.5
A20: Четверикова Ксения | B20: 2 | C20: 1 | D20: =SUM(B20:C20) -> 3
A21: Липко Владлена | B21: 7.5 | D21: 7.5
A22: Павликов Дмитрий | B22: 19 | D22: 19
A23: Гайденко Елена | B23: 9 | C23: 1 | D23: 10
A24: Абдуллаева Джамиля | B24: 5 | C24: 5 | D24: =SUM(B24:C24) -> 10
A25: Пашкова Анна | B25: 15 | C25: 0 | D25: =SUM(B25:C25) -> 15
A26: Коломеец Екатерина | B26: 1 | C26: 2 | D26: =SUM(B26:C26) -> 3
A27: Гусева Алеся | C27: 8 | D27: 8
A28: Шашерина Дана | B28: 0 | C28: 0 | D28: =SUM(B28:C28) -> 0
A29: ??? | B29: 9 | D29: 9
A30: Малкова Полина | B30: 12 | D30: 12

Sheet Заменыотмены
A1: Педагог | B1: Класс | C1: Предмет | D1: Дата | E1: Решение | G1: Класс | H1: Предмет | I1: Даты | J1: Отработка
A2: Павликов | B2: 5А | C2: история | D2: 45989 | E2: заменили анг.яз (Шашерина) и биологией | G2: 6а | H2: анг.яз | I2: 26.01, 30.01, 2.02, 9.02 | J2: 11.02 -отработка урока за 26.01, 18.02 - отработка урока за 30.01
B3: 7А | C3: история | E3: отмена урока | G3: 6б | H3: анг.яз | I3: 26.01, 02.02
A4: Чеченкова | B4: 3в, 4в | C4: окр.мир | D4: 45989 | E4: заменили Конохов и Пашкова | G4: 6а | H4: математика | I4: 46059
A5: Савина | B5: 3а | C5: окр.мир | D5: 45989 | E5: отмена урока | G5: 6б | H5: математика | I5: 46059
B6: 1а | C6: математика | D6: 45989 | E6: отмена урока | G6: 7б | H6: геометрия | I6: 46062
B7: 1б | C7: математика | D7: 45989 | E7: заменила Джамиля | G7: 7б | H7: информатика | I7: 46062
B8: 2б | C8: математика | D8: 45989 | E8: заменила Анна Пашкова | G8: 7б | H8: анг.яз | I8: 46064
B9: 3б | C9: математика | D9: 45989 | E9: заменила Анна Пашкова | G9: 7а | H9: анг.яз | I9: 46064
A10: Пашкова | B10: 2в | C10: ом | D10: 45989 | E10: отмена урока,у Анны сгорел роутер | G10: 6а | H10: математика | I10: 46065
B11: 4б | C11: ом | D11: 45989 | E11: отмена урока,у Анны сгорел роутер
A12: Цуркан | D12: 1,2 декабря
A13: Чеченкова | B13: 4а | C13: математика | D13: 45993
B14: 3в | C14: ОМ
B15: 4в | C15: математика
A16: Ерохина | B16: 3б | C16: анг.яз | D16: 45994 | E16: замена Дутова А.
B17: 2б
B18: 2б | D18: 45995 | E18: замена Шашерина Д.
B19: 3б
B20: 2а | D20: 45996 | E20: замена Дутова А.
B21: 3в
B22: 3а
B23: 3б
A24: Четверикова | B24: 8а | C24: химия | D24: 45994 | E24: отмена урока
A25: Рассолова | B25: 2б | C25: сонастройка | D25: 45994 | E25: замена Козлова Г.
A26: Павликов | B26: 9а | C26: история | D26: 45999 | E26: замена на урок геометрии
A27: Чеченкова | B27: 3в | C27: окружающий мир | D27: 46010 | E27: замена Конохов Павел
A28: Аношко | B28: 3а, б,в | C28: продленка | D28: 46007 | E28: замена Силовьева Алла
A29: Рассолова | B29: 1а, 1б | C29: все | D29: 46007 | E29: замена Коновалова
A30: Рассолова | B30: 1а, 1б | D30: 46008 | E30: замена Коновалова и Савина
A31: Чеченкова | B31: 4а, 4в, 3в | C31: ОМ | D31: 46015 | E31: 4а - Джамиля, 3в - Аношко, 4в - Цуркан
A32: Ерохина | B32: 3в, 2а | C32: анг.яз | D32: 46015 | E32: отмена уроков
A33: Чеченкова | B33: 3в, 4а,4а | C33: математика/ОМ | D33: 46034 | E33: 3в - замена Аношко, 4а - замена Коновалова на оба урока, 4в- отмена урока
A34: Чеченкова | B34: 3в, 4в | C34: математика/ОМ | D34: 46035 | E34: 3в - замена Аношко, 4в- отмена урока
A35: Липко | B35: 7а, 7б, 9а | C35: физика | D35: 46036 | E35: отмена уроков
A36: Чеченкова | B36: 3в, 4а, 4в | C36: математика/ОМ | D36: 46036 | E36: 3в - замена Аношко, 4в - замена Цуркан, 4а - отмена урока
A37: Вайнула | B37: 7б | C37: русский язык | D37: 46038 | E37: отмена урока
A38: Ларшина | B38: 8а,7Б, 7а | C38: алгебра | D38: 46041 | E38: отмена уроков
A39: Ларшина | B39: 8а, 9а, 7а, 7а | C39: алгебра, геометрия | D39: 46042 | E39: 9а - замена Каранушенко, 8а, 7а - отмена уроков
A40: Вайнула | B40: 6а, 6б, 7а, 7б | D40: 46049 | E40: отмена всех уроков
...

Sheet Учебный план
A1: Часов в неделю ПЛАН | M1: Часов в неделю ФАКТ (проверка)
A2: № | B2: Название | C2: 1 | D2: 2 | E2: 3 | F2: 4 | G2: 5 | H2: 6 | I2: 7 | J2: 8 | K2: 9 | M2: 1А | N2: =COUNTA('Расписание'!D3:D55) -> 1
A3: 1 | B3: Русский язык | C3: 2 | D3: 3 | E3: 3 | F3: 3 | G3: 3 | H3: 3 | I3: 3 | J3: 3 | K3: 3 | M3: 1Б | N3: =COUNTA('Расписание'!E3:E55) -> 1
A4: 2 | B4: Литература | C4: 2 | D4: 2 | E4: 2 | F4: 2 | G4: 2 | H4: 2 | I4: 2 | J4: 2 | K4: 2 | M4: 1В | N4: =COUNTA('Расписание'!F3:F55) -> 1
A5: 3 | B5: Математика | C5: 3 | D5: 3 | E5: 3 | F5: 3 | G5: 3 | H5: 3 | I5: 0 | J5: 0 | K5: 0 | M5: 2А | N5: =COUNTA('Расписание'!G3:G55) -> 1
A6: 4 | B6: Окружающий мир | C6: 2 | D6: 2 | E6: 2 | F6: 2 | G6: 0 | H6: 0 | I6: 0 | J6: 0 | K6: 0 | M6: 2Б | N6: =COUNTA('Расписание'!H3:H55) -> 1
A7: 5 | B7: Английский язык | C7: 0 | D7: 3 | E7: 3 | F7: 3 | G7: 3 | H7: 3 | I7: 3 | J7: 3 | K7: 3 | M7: 2В | N7: =COUNTA('Расписание'!I3:I55) -> 1
A8: 6 | B8: Музыка | C8: 0.5 | D8: 0.5 | E8: 0.5 | F8: 0.5 | G8: 0 | H8: 0 | I8: 0 | J8: 0 | K8: 0 | L8: Сам. изучение | M8: 3А | N8: =COUNTA('Расписание'!J3:J55) -> 1
A9: 7 | B9: Физкультура | C9: 0.5 | D9: 0.5 | E9: 0.5 | F9: 0.5 | G9: 0 | H9: 0 | I9: 0 | J9: 0 | K9: 0 | L9: Добавить: | M9: 3Б | N9: =COUNTA('Расписание'!K3:K56) -> 1
A10: 8 | B10: ИЗО | C10: 0.5 | D10: 0.5 | E10: 0.5 | F10: 0.5 | G10: 0 | H10: 0 | I10: 0 | J10: 0 | K10: 0 | L10: ОБЗР | M10: 3В | N10: =COUNTA('Расписание'!K4:K57) -> 1
A11: 9 | B11: Технология | C11: 0.5 | D11: 0.5 | E11: 0.5 | F11: 0.5 | G11: 0 | H11: 0 | I11: 0 | J11: 0 | K11: 0 | L11: Вероятность и статистика | M11: 4А | N11: ='Расписание'!M2 -> #REF!
A12: 10 | B12: Алгебра | C12: 0 | D12: 0 | E12: 0 | F12: 0 | G12: 0 | H12: 0 | I12: 3 | J12: 3 | K12: 3 | L12: ОДНКР (5 и 6 кл.) | M12: 4Б | N12: ='Расписание'!N2 -> #REF!
A13: 11 | B13: Геометрия | C13: 0 | D13: 0 | E13: 0 | F13: 0 | G13: 0 | H13: 0 | I13: 2 | J13: 2 | K13: 2 | M13: 4В | N13: ='Расписание'!O2 -> #REF!
A14: 12 | B14: Биология | C14: 0 | D14: 0 | E14: 0 | F14: 0 | G14: 1 | H14: 1 | I14: 1 | J14: 1 | K14: 1.5 | M14: 5А | N14: ='Расписание'!P2 -> #REF!
A15: 13 | B15: История | C15: 0 | D15: 0 | E15: 0 | F15: 0 | G15: 2 | H15: 2 | I15: 2 | J15: 2 | K15: 1 | M15: 5Б | N15: ='Расписание'!Q2 -> #REF!
A16: 14 | B16: Обществознание | C16: 0 | D16: 0 | E16: 0 | F16: 0 | G16: 0 | H16: 0 | I16: 0 | J16: 1 | K16: 1 | M16: 5В | N16: ='Расписание'!R2 -> #REF!
A17: 15 | B17: География | C17: 0 | D17: 0 | E17: 0 | F17: 0 | G17: 1 | H17: 1 | I17: 1 | J17: 1 | K17: 1 | M17: 6А | N17: ='Расписание'!S2 -> #REF!
A18: 16 | B18: Физика | C18: 0 | D18: 0 | E18: 0 | F18: 0 | G18: 0 | H18: 0 | I18: 2 | J18: 2 | K18: 1.5 | M18: 6Б | N18: 21
A19: 17 | B19: Информатика | C19: 0 | D19: 0 | E19: 0 | F19: 0 | G19: 0 | H19: 0 | I19: 1 | J19: 1 | K19: 1 | M19: 6В | N19: 21
A20: 18 | B20: Химия | C20: 0 | D20: 0 | E20: 0 | F20: 0 | G20: 0 | H20: 0 | I20: 0 | J20: 1 | K20: 1 | M20: 7А | N20: 26
A21: 19 | B21: Сонастройка | C21: 0 | D21: 0 | E21: 0 | F21: 0 | G21: 0 | H21: 0 | I21: 0 | J21: 0 | K21: 0 | M21: 8А | N21: 28
A22: 20 | B22: Тьюторский час | C22: 1 | D22: 1 | E22: 1 | F22: 1 | G22: 1 | H22: 1 | I22: 1 | J22: 1 | K22: 1 | M22: 9А | N22: 27
C23: =SUM(C3:C22) -> 12 | D23: =SUM(D3:D22) -> 16 | E23: =SUM(E3:E22) -> 16 | F23: =SUM(F3:F22) -> 16 | G23: =SUM(G3:G22) -> 16 | H23: =SUM(H3:H22) -> 16 | I23: =SUM(I3:I22) -> 21 | J23: =SUM(J3:J22) -> 23 | K23: =SUM(K3:K22) -> 22
B24: кол-во классов | C24: 3 | D24: 3 | E24: 3 | F24: 3 | G24: 3 | H24: 3 | I24: 1 | J24: 1 | K24: 1
C25: =C23*C24 -> 36 | D25: =D23*D24 -> 48 | E25: =E23*E24 -> 48 | F25: =F23*F24 -> 48 | G25: =G23*G24 -> 48 | H25: =H23*H24 -> 48 | I25: =I23*I24 -> 21 | J25: =J23*J24 -> 23 | K25: =K23*K24 -> 22 | L25: =SUM(C25:K25) -> 342
L27: Первый модуль | M27: =L25*8 -> 2736
L28: Сентябрь | M28: =L25*4-2*42 -> 1284

Sheet Индивидуалы (свободные слоты)
A1: Педагог | B1: Предмет | C1: Понедельник | D1: Вторник | E1: Среда | F1: Четверг | G1: Пятница
A2: Коломеец Екатерина | B2: история, обществознание, география | C2: 10:30 - 11:00 | D2: c 12/30 | F2: 10:30 - 11:00 | G2: c 12/30
A3: Карнаушенко Оксана | B3: математика (среднее звено) | C3: 13.00-16.00 | D3: 13.00-16.00 | E3: 13.00-16.00 | F3: 13.00-16.00
A4: Ерохина Анастасия | B4: анг.яз | C4: готова брать индивидуалов, но лучше лично уточнять по времени
A5: Петрова Елизавета | B5: рус.яз, литература | D5: 11.45-13.25 | E5: 12.40-14.20 | F5: 9.55-10.40, 11.45-13.25
A6: Пашкова Анна | B6: нач.школа (все предметы) + ПКШ + математика (5-7 класс), русский язык (5-6 класс) | C6: 11.45–12.30 12.40–13.25 | E6: 10.50–11.35 11.45–12.30, 13.35–14.20 | G6: 12.40–13.25 13.35–14.20
A7: Абдуллаева Джамиля | B7: нач. школа (можно все предметы) | C7: 10.50-15.00 | D7: 9.55–10.40, 11.45-15.00 | E7: 10.50-15.00 | F7: 9.00-15.00 | G7: 9.00–9.45, 10.50-15.00
A8: Дутова Анна | B8: английский язык | C8: 12.30 - 15.30 | D8: 9.00-15.30 | E8: 9.55–10.40, 12.40–13.25, 14.30-15.30 | F8: 11.45–12.30, 13.30-15.30 | G8: 10.50–11.35 11.45–12.30, 13.30-15.30
A9: Зиновьева Александра | B9: английский язык | C9: 10.50–14.30 | D9: 9.55–10.40, 11.45 - 14.30 | F9: 09.00-11.35, 13.35–14.20 | G9: 9.00–9.45, 10.50–11.35, 12.40–14.20
A10: Чеченкова Светлана | B10: нач.школа (математика, ОМ) | C10: готова брать индивидуалов, но лучше лично уточнять по времени
A11: Павленко Ольга | B11: биология | C11: готова брать индивидуалов, но лучше лично уточнять по времени
A12: Четверикова Ксения | B12: химия | C12: нужно уточнить время
A13: Гайденко Елена | B13: география | C13: нужно уточнить время, у нее не много слотов, но есть Коломеец

Sheet Матрица кружки
B1: Шельпякова Мария (книготерапия, фин.грамотность) | H1: Шельпякова Мария (книготерапия, фин.грамотность)
B2: понедельник | C2: вторник | D2: среда | E2: четверг | F2: пятница | H2: понедельник | I2: вторник | J2: среда | K2: четверг | L2: пятница
C3: 9.00 | D3: 9.00 | E3: 9.00 | I3: 9.00 | J3: 9.00 | K3: 9.00
B4: 10.00 | C4: 10.00 | D4: 10.00 | E4: 10.00 | F4: 10.00 | H4: 10.00 | I4: 10.00 | J4: 10.00 | K4: 10.00 | L4: 10.00
B5: 15.00 | D5: 15.00 | E5: 15.00 | H5: 15.00 | K5: 15.00
B7: Claude Aghesom (разговорный клуб) | H7: Claude Aghesom (разговорный клуб)
B8: понедельник | C8: вторник | D8: среда | E8: четверг | F8: пятница | H8: понедельник | I8: вторник | J8: среда | K8: четверг | L8: пятница
B9: 8.00-9.45 | C9: 8.00-9.00 | D9: 8.00-14.00 | E9: 8.00-14.00 | F9: 8.00-9.00 | H9: 8.00-9.45 | I9: 8.00-9.00 | J9: 8.00-14.00 | K9: 8.00-14.00 | L9: 8.00-9.00
B10: 14.30-16.00 | C10: 10.00-11.00 | F10: 11.00-14.00 | H10: 14.30-16.00 | I10: 10.00-11.00 | L10: 11.00-14.00
C11: 12.00-14.00 | I11: 12.00-14.00
B13: Сокольская Татьяна | H13: Сокольская Татьяна
B14: Каллиграфия | H14: Каллиграфия
B15: понедельник | C15: вторник | D15: среда | E15: четверг | F15: пятница | H15: понедельник | I15: вторник | J15: среда | K15: четверг | L15: пятница
B16: 15.00 | F16: 15.00 | I16: 15.00 | K16: 15.00
B17: Умение учиться | H17: Умение учиться/чтение
C18: 14.00 (3-4 классы) | E18: 14.00 (3-4 классы) | H18: 16.00 (1-2 кл) | J18: 16.00 (1-2 кл)
B19: 16.00 (1-2 класс) | F19: 16.00 (1-2 класс) | H19: 17.00 (5-7 кл) | J19: 17.00 (5-7 кл)
B20: 17.00 (5-7 классы) | F20: 17.00 (5-7 классы)
H22: Коновалова Евгения
H23: ЭИ/гибкие навыки
H24: понедельник | I24: вторник | J24: среда | K24: четверг | L24: пятница
H25: 9.00 | I25: 9.00 | J25: 9.00 | K25: 9.00 | L25: 9.00
H26: 10.00 | I26: 10.00 | K26: 10.00 | L26: 10.00
I27: 11.00 | K27: 11.00 | L27: 11.00
I28: 12.00 | J28: 12.00 | K28: 12.00 | L28: 12.00
H30: 17.00 | I30: 17.00 | J30: 17.00 | K30: 17.00 | L30: 17.00
H32: Claude Aghesom (разговорный клуб)
H33: понедельник | I33: вторник | J33: среда | K33: четверг | L33: пятница
H35: 14.30
H36: 15.30
H38: Голубева Елизавета
H39: ЭИ/гибкие навыки
H40: понедельник | I40: вторник | J40: среда | K40: четверг | L40: пятница
H42: 16.00 | J42: 16.00

Sheet Матрица индивидуалов
A1: Слоты учеников (тариф 1) | H1: Слоты учеников (тариф 2) | P1: Кашапов Борис | V1: Расписание Ви Дая | AB1: Расписание Ви Дая
B2: понедельник | C2: вторник | D2: среда | E2: четверг | F2: пятница | I2: понедельник | J2: вторник | K2: среда | L2: четверг | M2: пятница | P2: понедельник | Q2: вторник | R2: среда | S2: четверг | T2: пятница | V2: понедельник | W2: вторник | X2: среда | Y2: четверг | Z2: пятница | AB2: понедельник | AC2: вторник | AD2: среда | AE2: четверг | AF2: пятница
A3: 09.00 | B3: Фисюк Даша 7 класс до 11.30 | C3: Фисюк Даша 7 класс до 11.30 | D3: Фисюк Даша 7 класс до 11.30 | E3: Фисюк Даша 7 класс до 11.30 | F3: Фисюк Даша 7 класс до 11.30 | H3: 09.00 | I3: 9.30-10.15 - Математика Харченко Педагог Гусева Алеся | J3: 9.30-11.15 - РЯ Харченко педагог Гусева Алеся | K3: 9.30-10.15 - Математика Харченко Педагог Гусева Алеся | L3: 9.30-11.15 - РЯ Харченко педагог Гусева Алеся | M3: 9.30-10.15 - Математика Харченко Педагог Гусева Алеся | P3: 11.00-11.45 - математика | R3: 11.00-11.45 - математика | T3: 11.00-11.45 - математика | W3: 9.00 - 9.45 Математика (педагог Пашкова Анна) | X3: 09.00-9.45 - обучение грамоте (педагог Абдуллаева Джамиля) | Y3: 9.00 - 9.45 Математика (педагог Пашкова Анна) | AD3: 09.00-9.45 - обучение грамоте | AE3: 9.00 - 9.45 Математика | AF3: 9.00 - 9.45 Окружающий мир
A4: 10.00 | H4: 10.00 | I4: 10.25-11.15 - Окружающий мир Харченко педагог Гусева Алеся | J4: 10.25-11.15 литература Харченко педагог Гусева | K4: 10.25-11.15 ЭИ Харченко тьютор Коновалова | L4: 10.25-11.15 литература Харченко педагог Гусева | P4: 12.00-12.45 - обучение грамоте | R4: 12.00-12.45 - обучение грамоте | T4: 12.00-12.45 - обучение грамоте | V4: 9.55 -10.40 - обучение грамоте (педагог Абдуллаева Джамиля) | Z4: 9.55 - 10.40 Окружающий мир (педагог Пашкова Анна) | AB4: 9.55 -10.40 - обучение грамоте
A5: 11.00 | H5: 11.00 | I5: 11.30-12.15 - Английский Харченко педагог Дутова | K5: 11.30-12.15 - Английский Харченко педагог Дутова | AC5: 11.00-11.45 Математика
A6: 12.00 | I6: 11.00-11.45 - математика Кашапов педагог Абдаллуева | K6: 11.00-11.45 - математика Кашапов педагог Абдаллуева | M6: 11.00-11.45 - математика Кашапов педагог Абдаллуева
H7: 12.00 | I7: 12.00-12.45 - обучение грамоте Кашапов педагог Абдаллуева | K7: 12.00-12.45 - обучение грамоте Кашапов педагог Абдаллуева | M7: 12.00-12.45 - обучение грамоте Кашапов педагог Абдаллуева
A8: 13.00 | H8: 13.00 | V8: изменения в расписании 19.01-30.01
A9: 14.00 | H9: 14.00 | P9: Расписание Харченко Матвей | V9: Расписание Харченко Матвей
A10: 15.00 | B10: Кудисова Настя 9 класс | H10: 15.00 | P10: понедельник | Q10: вторник | R10: среда | S10: четверг | T10: пятница | V10: понедельник | W10: вторник | X10: среда | Y10: четверг | Z10: пятница
A11: 16.00 | H11: 16.00 | J11: Фериченков Виктор (самостоятельный тариф. Нужна программа начальной школы. Будет 8 уроков в месяц + доп задания по не основным предметам) РЯ - педагог Петрова | L11: Фериченков Виктор (самостоятельный тариф. Нужна программа начальной школы. Будет 8 уроков в месяц + доп задания по не основным предметам) РЯ - педагог Петрова | P11: 9.30-10.15 - математика | R11: 09.30-10.15 математика | S11: 09.30-10.15 русский язык | T11: 09.30-10.15 математика | V11: 12.00-12.45 - математика | W11: 12.35-13.20 эмоциональный интеллект | Y11: 12.00-12.45 русский язык | Z11: 12.00-12.45 математика
A12: 17.00 | H12: 17.00 | P12: 10.25-11.10 - окружающий мир | R12: 10.25-11.10 эмоциональный интеллект | S12: 10.25-11.10 литературное чтение | T12: 10.25-11.10 русский язык | V12: 12.55-13.40- окружающий мир | W12: 13.30-14.15 - математика | Y12: 12.55-13.40 литературное чтение | Z12: 12.55-13.40 русский язык
A13: 18.00 | H13: 18.00 | J13: Николаев Кирилл (самостоятельный тариф, грамота, математика, ОМ) + доп.занятия по не основным предметам | M13: Николаев Кирилл (грамота, математика, ОМ) + доп.занятия по не основным предметам | P13: 12.40 - 13.25 - английский язык | R13: 12.40 - 13.25 - английский язык | T13: 11.20-12.10 литературное чтение | Z13: 13.50-14.35 литературное чтение
E15: Слоты педагогов
E16: педагог | F16: предмет | G16: понедельник | H16: вторник | I16: среда | J16: четверг | K16: пятница
E17: Коломеец | F17: история | G17: 10:30 - 11:00 | H17: c 12/30 | J17: 10:30 - 11:00 | K17: c 12/30
E18: Латышева | F18: анг.яз | G18: не берет индивидуалов
E19: Карнаушенко | F19: математика | G19: 13.00-16.00 | H19: 13.00-16.00 | I19: 13.00-16.00 | J19: 13.00-16.00 | O19: понедельник | P19: вторник | Q19: среда | R19: четверг | S19: пятница | V19: Расписание Сергеева Марта
E20: Кулик Лариса | F20: рус.яз (средняя школа) | G20: 9.00-14.00 | H20: 9.00-14.00 | I20: 9.00-14.00 | J20: 9.00-14.00 | K20: 9.00-14.00 | O20: индивидуал 3 с 9.00 до 12.00 1 класс (СДВГ) (все предметы) | P20: индивидуал 3 с 9.00 до 12.00 1 класс (СДВГ) (все предметы) | Q20: индивидуал 3 с 9.00 до 12.00 1 класс (СДВГ) (все предметы) | R20: индивидуал 3 с 9.00 до 12.00 1 класс (СДВГ) (все предметы) | S20: индивидуал 3 с 9.00 до 12.00 1 класс (СДВГ) (все предметы) | V20: понедельник | W20: вторник | X20: среда | Y20: четверг | Z20: пятница
E21: Ерохина | F21: анг.яз | G21: нужно уточнять, большая нагрузка | O21: индивидуал 4 15.00 или 16.00 анг.яз (подтянуть по программе 6 класса), кол-ва раз в неделю можно обговорить | P21: индивидуал 1 16.00 - 1 класс (все предметы) | R21: индивидуал 1 16.00 - 1 класс (все предметы) | X21: 09.00-09.45 Английский язык (педагог Матвеева Валерия)
E22: Михайлова | F22: математика | G22: не берет индивидуалов | P22: индивидуал 2 18.00 - 1 класс (все предметы) | S22: индивидуал 2 18.00 - 1 класс (все предметы) | V22: 9.55 - 10.40 Английский язык (педагог Матвеева Валерия) | Z22: 10.50-11.35 Английский язык (педагог Матвеева Валерия)
E23: Савина | F23: началка (матем., ОМ) | O23: индивидуал 5 16.00 или 17.00 - русский язык и математика (подтянуть по программе 9 класса) | V23: 11.40-12.25 Математика (педагог Чеченкова Светлана) | X23: 11.40-12.25 Математика (педагог Чеченкова Светлана) | Z23: 11.40-12.25 Математика (педагог Чеченкова Светлана)
E24: Мишина | F24: рус.яз, литература | G24: есть индивидуал, по остальным нужно уточнять | V24: 13.00-13.45 Русский язык (педагог Юманова Дарья) | X24: 13.00-13.45 Русский язык (педагог Юманова Дарья) | Z24: 13.00-13.45 Русский язык (педагог Юманова Дарья)
E25: Петрова | F25: рус.яз, литература | H25: 11.45-13.25 | I25: 12.40-14.20 | J25: 9.55-10.40, 11.45-13.25
E26: Норкина | F26: все предметы началки | G26: тяжело адаптируется, пока лучше не предлагать индивидуалов
E27: Тенешева | F27: русский язык, литература | G27: у нее факультативы по ОГЭ/ЕГЭ, поэтому не берет пока индивидуалов
E28: Вайнула | F28: русский язык, литература | G28: нужно уточнять, большая нагрузка
E29: Ларшина | F29: алгебра, геометрия, информатика | G29: нужно уточнять, большая нагрузка
E30: Павликов | F30: история | G30: нужно уточнять, большая нагрузка
E31: Павленко | F31: биология
E32: Липко | F32: физика
E33: Четверикова | F33: химия
E34: Чеченкова | F34: началка (матем., ОМ) | G34: нужно уточнять, большая нагрузка

Sheet резерв

Sheet Классы и часы учителя 
A1: Предмет | B1: Учитель | C1: Классы | D1: Нагрузка в неделю в группе
A2: Начальная школа
A3: Технология /ИЗО | B3: Бондарь Ольга | C3: 1а, 1б, 2а, 2б, 2в, 3а, 3б, 3в, 4а, 4б, 4в | D3: 11
A4: Английский язык | B4: Ерохина Анастасия | C4: 3а, 3а, 2а, 2б, 3б | D4: 15
A5: Английский язык | B5: Малкова Полина | C5: 4а, 4б, 4в, 2в | D5: 12
A6: Русский язык, Литература | B6: Козлова Галина | C6: 2а, 2б, 3а, 3б | D6: 20
A7: Математика, окружающий мир | B7: Чеченкова Светлана | C7: 3в, 4а, 4в | D7: 15
A8: Математика, окружающий мир | B8: Савина Ксения | C8: 1а, 1б, 2б, 3б, 3а | D8: 25
A9: Русский язык, Литература | B9: Абдуллаева Джамиля | C9: 2в | D9: 5
A10: Русский язык, Литература | B10: Петрова Елизавета | C10: 4а, 4б, 4в | D10: 15
A11: Физкультура | B11: Карабанова Маргарита | C11: 1а, 1б, 2а, 2б, 3а, 3б, 3в, 4а, 4б, 4в | D11: 11
A12: Математика,окружающий мир | B12: Пашкова Анна | C12: 2а, 2в, 4б | D12: 15
A13: Русский язык, Литература | B13: Конохов Павел | C13: 1а,1б, 3в | D13: 13
A14: Средняя школа
A15: Русский язык, Литература | B15: Анастасия Вайнула | C15: 6а, 6б, 7а, 7б | D15: 20
A16: Русский язык, Литература | B16: Тенешева Дарья | C16: 8а, 9а | D16: 10
A17: Русский язык, Литература | B17: Мишина Валерия | C17: 5а, 5б, 5в | D17: 15
A18: Алгебра, геометрия, информатика | B18: Ларшина Анастасия | C18: 7а, 8а, 9а | D18: 19
A19: Математика | B19: Михайлова Марина | C19: 5а, 5б, 5в | D19: 9
A20: Математика | B20: Карнаушенко Оксана | C20: 6а, 6б, 7б | D20: 11
A21: Биология | B21: Павленко Ольга | C21: 5а, 5б, 5в, 6а, 6б, 7а, 7б, 8а, 9а | D21: 9
A22: Химия | B22: Четверикова Ксения | C22: 8а, 9а | D22: 2
A23: Физика | B23: Липко Владлена | C23: 7а, 7б, 8а, 8б, 9а | D23: 7
A24: История, обществознание | B24: Павликов Дмитрий | C24: 5а, 5б, 5в, 6а, 6б, 7а, 7б, 8а, 9а | D24: 19
A25: Английский язык | B25: Зиновьева Александра | C25: 6а, 6б, 7а, 7б | D25: 12
A26: Английский язык | B26: Латышева Ирина | C26: 8а, 9а | D26: 6
A27: География | B27: Гайденко Елена | C27: 5а, 5б, 5в, 6а, 6б, 7а, 7б, 8а, 9а | D27: 9
A28: Начальная + средняя школа
A33: Индивидуальные

Sheet ПКШ
A1: Подготовка к школе
A2: Время | B2: Понедельник | C2: Вторник | D2: Среда | E2: Четверг | F2: Пятница
A3: 13.35-13.50 | C3: Сонастройка | E3: Сонастройка
A4: 13.50-14.15 | C4: Обучение грамоте и развитие речи | E4: Обучение грамоте и развитие речи
A5: 14.25-14.50 | C5: Математика | E5: Математика
A6: 15.00-15.25 | C6: Окружающий мир | E6: Тьюторский час
A7: Тьютор - Коновалова Евгения
A8: Педагог Пашкова Анна

Sheet 1А
A1: Тьютор | B1: Рассолова Екатерина
A2: Время | B2: Понедельник | C2: Вторник | D2: Среда | E2: Четверг | F2: Пятница | H2: 45989 | J2: 45989 | L2: 46007 | Q2: 45924
A3: 8.45-9.00 | B3: Сонастройка Рассолова | C3: Сонастройка Рассолова | D3: Сонастройка Рассолова | E3: Сонастройка Рассолова | F3: Сонастройка Рассолова | H3: Сонастройка | J3: Сонастройка | L3: Сонастройка | Q3: Сонастройка
A4: 9.00-9.45 | B4: Русский язык Пашкова | C4: Математика Савина | D4: Русский язык Пашкова | E4: Физкультура Карабанова | F4: Технология Бондарь | H4: ИЗО | J4: Тьюторский час | L4: Математика | Q4: Окружающий мир
A5: 9.55-10.40 | B5: Окружающий мир Савина | C5: Литературное чтение Пашкова | D5: Математика Савина | E5: Окружающий мир Савина | F5: Математика Савина | H5: Тьюторский час | J5: ИЗО | L5: Обучение грамоте | Q5: Математика
A6: 10.50-11.35 | C6: тьюторский час Рассолова | E6: Литературное чтение Пашкова
A7: 11.35-15.00 | B7: ОБЕД
A8: 15.00-16.00 | B8: Продленка групповая Рассолова Екетерина
A9: 16.00-17.00 | B9: Творческая мастерская (Рассолова Екатерина) | C9: Творческая мастерская (Рассолова Екатерина) | D9: Творческая мастерская (Рассолова Екатерина)
A12: 1А | B12: Тьютор Коновалова Евгения
A13: Время | B13: Понедельник | C13: Вторник | D13: Среда | E13: Четверг | F13: Пятница
A14: 8.45-9.00 | B14: Сонастройка Коновалова | C14: Сонастройка Пашкова | D14: Сонастройка Коновалова | E14: Сонастройка Пашкова | F14: Сонастройка Коновалова
A15: 9.00-9.45 | B15: Русский язык Пашкова | C15: Математика Савина | D15: Русский язык Пашкова | E15: тьюторский час Коновалова | F15: Технология Бондарь
A16: 9.55-10.40 | B16: Окружающий мир Савина | C16: Литературное чтение Пашкова | D16: Математика Савина | E16: Окружающий мир Савина | F16: Математика Савина
A17: 10.50-11.35 | B17: Музыка Карпова | E17: Литературное чтение Пашкова
A18: 11.35-15.00 | B18: ОБЕД
A19: 15.00-16.00 | B19: Продленка групповая Юманова Дарья
A20: 16.00-17.00 | B20: Творческая мастерская (Коновалова Евгения) | C20: Творческая мастерская (Коновалова Евгения) | D20: Творческая мастерская (Коновалова Евгения)

Sheet 1Б
A1: Тьютор | B1: Рассолова Екатерина
A2: Время | B2: Понедельник | C2: Вторник | D2: Среда | E2: Четверг | F2: Пятница | H2: Вторник | K2: 45924 | M2: 45980 | O2: 46064
A3: 11.30-11.45 | B3: Сонастройка Коновалова | C3: Сонастройка Савина | D3: Сонастройка Коновалова | E3: Сонастройка Савина | F3: Сонастройка Коновалова | H3: Сонастройка Рассолова | K3: Сонастройка | M3: Сонастройка | O3: Сонастройка
A4: 11.45-12.30 | B4: Окружающий мир Савина | C4: Математика Савина | D4: Математика Савина | E4: Русский язык Пашкова | F4: Математика Савина | H4: Математика Савина | K4: Математика | M4: Математика | O4: Математика
A5: 12.40-13.25 | B5: Технология Бондарь | C5: Русский язык Пашкова | D5: Литературное чтение Пашкова | E5: Окружающий мир Савина | F5: Литературное чтение Пашкова | H5: Обучение грамоте Колтакова | K5: Эмоциональный интеллект | M5: Обучение грамоте | O5: Обучение грамоте
A6: 13.35 -14.20 | B6: Музыка Карпова | D6: Тьюторский час Рассолова | M6: ИЗО | O6: Технология
A7: 14.20-15.00 | B7: ОБЕД
A8: 15.00-16.00 | B8: Продленка групповая Рассолова Екетерина
A9: 16.00-17.00 | B9: Творческая мастерская (Рассолова Екатерина) | C9: Творческая мастерская (Рассолова Екатерина) | D9: Творческая мастерская (Рассолова Екатерина)

Sheet 2А
A1: Тьютор | B1: Силосьева Алла
A2: Время | B2: Понедельник | C2: Вторник | D2: Среда | E2: Четверг | F2: Пятница
A3: 8.45-9.00 | B3: Сонастройка Силосьева Алла | C3: Сонастройка Козлова | D3: Сонастройка Козлова | E3: Сонастройка Силосьева Алла | F3: Сонастройка Козлова | J3: 45929 | L3: 45930 | N3: 45931 | P3: 45938 | S3: 45940 | U3: 46015
A4: 9.00-9.45 | B4: Математика Пашкова | C4: ИЗО Бондарь | D4: Русский язык Козлова | E4: Литература Козлова | F4: Литература Козлова | J4: Сонастройка | L4: Сонастройка | N4: Сонастройка | P4: Сонастройка | S4: Сонастройка | U4: Сонастройка
A5: 9.55-10.40 | B5: Русский язык Козлова | C5: Русский язык Козлова | D5: Окружающий мир Пашкова | E5: Математика Пашкова | F5: Английский язык Ерохина | J5: Математика | L5: ИЗО | N5: Русский язык | P5: Русский язык | S5: Литература | U5: Русский язык
A6: 10.50-11.35 | B6: Окружающий мир Пашкова | C6: Математика Пашкова | D6: Английский язык Ерохина | E6: Физкультура Карабанова | F6: Тьюторский час Силосьева | J6: Русский язык | L6: Русский язык | N6: Окружающий мир | P6: Окружающий мир | S6: Эмоциональный интеллект | U6: Окружающий мир
A7: 11.45-12.30 | B7: Английский язык Ерохина | J7: Английский язык | L7: Английский язык | N7: Математика | P7: Математика
A8: 12.30-15.00 | B8: ОБЕД
A9: 15.00-16.00 | B9: Продленка Коновалова Евгения
A10: 16.00-17.00 | B10: Творческая мастерская (Силосьева Алла) | C10: Творческая мастерская (Цуркан Юлия) | D10: Творческая мастерская (Аношко Лиана)
A12: ИЗМЕНЕНИЯ с 8.12
A13: Тьютор | B13: Силосьева Алла
A14: Время | B14: Понедельник | C14: Вторник | D14: Среда | E14: Четверг | F14: Пятница
A15: 8.45-9.00 | B15: Сонастройка Козлова | C15: Сонастройка Козлова | D15: Сонастройка Козлова | E15: Сонастройка Силосьева Алла | F15: Сонастройка Козлова
A16: 9.00-9.45 | B16: Русский язык Козлова | C16: Технология Бондарь | D16: Русский язык Козлова | E16: Литература Козлова | F16: Литература Козлова
A17: 9.55-10.40 | B17: Окружающий мир Пашкова | C17: Русский язык Козлова | D17: Окружающий мир Пашкова | E17: Математика Пашкова | F17: Английский язык Ерохина
A18: 10.50-11.35 | B18: Английский язык Ерохина | C18: Математика Пашкова | D18: Английский язык Ерохина | E18: Тьюторский час Силосьева | F18: Математика Пашкова
A19: 11.45-12.30 | B19: Музыка Карпова
A20: 12.30-15.00 | B20: ОБЕД
A21: 15.00-16.00 | B21: Продленка Коновалова Евгения
A22: 16.00-17.00 | B22: Творческая мастерская (Силосьева Алла) | C22: Творческая мастерская (Цуркан Юлия) | D22: Творческая мастерская (Аношко Лиана)
A24: 2А | B24: Тьютор Силосьева Алла
A25: Время | B25: Понедельник | C25: Вторник | D25: Среда | E25: Четверг | F25: Пятница
A26: 8.45-9.00 | B26: Сонастройка Козлова | C26: Сонастройка Козлова | D26: Сонастройка Козлова | E26: Сонастройка Силосьева Алла | F26: Сонастройка Козлова
A27: 9.00-9.45 | B27: Русский язык Козлова | C27: Технология Бондарь | D27: Русский язык Козлова | E27: Литература Козлова | F27: Литература Козлова
A28: 9.55-10.40 | B28: Музыка Карпова | C28: Русский язык Козлова | D28: Окружающий мир Пашкова | E28: Окружающий мир Пашкова | F28: Английский язык Ерохина
A29: 10.50-11.35 | B29: Английский язык Ерохина | C29: Математика Пашкова | D29: Английский язык Ерохина | E29: Тьюторский час Силосьева | F29: Математика Пашкова
A30: 11.45-12.30 | B30: Математика Пашкова
A31: 12.30-15.00 | B31: ОБЕД
A32: 15.00-16.00 | B32: Продленка Коновалова Евгения
A33: 16.00-17.00 | B33: Творческая мастерская (Силосьева Алла) | C33: Творческая мастерская (Цуркан Юлия) | D33: Творческая мастерская (Аношко Лиана)

Sheet 2Б
A1: Тьютор | B1: Рассолова Екатерина
A2: Время | B2: Понедельник | C2: Вторник | D2: Среда | E2: Четверг | F2: Пятница | I2: 45940
A3: 11.30-11.45 | B3: Сонастройка | C3: Сонастройка Ерохина | D3: Сонастройка Козлова Галина | E3: Сонастройка Козлова | F3: Сонастройка Козлова Галина | I3: Сонастройка
A4: 11.45-12.30 | B4: Русский язык Козлова | C4: Английский язык Ерохина | D4: Русский язык Козлова | E4: Литература Козлова | F4: Технология Бондарь | I4: ИЗО
A5: 12.40-13.25 | B5: Окружающий мир Савина | C5: Математика Савина | D5: Математика Савина | E5: Английский язык Ерохина | F5: Математика Савина | I5: Русский язык
A6: 13.35-14.20 | B6: тьюторский час Коновалова | C6: Литература Козлова | D6: Английский язык Ерохина | E6: Окружающий мир Савина | F6: Русский язык Козлова | I6: Математика
A7: 14.30-15.15 | B7: Музыка Карпова
A8: 14.20- 15.00 | B8: ОБЕД
A9: 15.00-16.00 | B9: Продленка Коновалова | D9: Продленка Коновалова | E9: Продленка Коновалова
A10: 16.00-17.00 | B10: Творческая мастерская (Силосьева Алла) | C10: Творческая мастерская (Цуркан Юлия) | D10: Творческая мастерская (Аношко Лиана)

Sheet 2В
A1: Тьютор | B1: Тьютор Рассолова Екатерина
A2: Время | B2: Понедельник | C2: Вторник | D2: Среда | E2: Четверг | F2: Пятница | O2: 46008 | Q2: 46014
A3: 8.45-9.00 | B3: Сонастройка Абдуллаева | C3: Сонастройка Пашкова | D3: Сонастройка Абдуллаева | E3: Сонастройка Абдуллаева | F3: Сонастройка Пашкова | O3: Сонастройка | Q3: Сонастройка
A4: 9.00-9.45 | B4: Русский язык Абдуллаева | C4: Окружающий мир Пашкова | D4: Русский язык Абдуллаева | E4: Технология Бондарь | F4: Математика Пашкова | O4: Литературное чтение | Q4: Окружающий мир
A5: 9.55-10.40 | B5: Английский язык Малкова | C5: Литературное чтение Абдуллаева | D5: Английский язык Малкова | E5: Английский язык Малкова | F5: Окружающий мир Пашкова | O5: Английский язык | Q5: Русский язык
A6: 10.50-11.35 | B6: Математика Пашкова | C6: Физкультура Карабанова | D6: Математика Пашкова | E6: Литературное чтение Абдуллаева | F6: Русский язык Абдуллаева | O6: Математика | Q6: Русский язык
A7: 11.45-12.30 | F7: Тьюторский час Рассолова
A8: 12.30-15.00 | B8: ОБЕД
A9: 15.00-16.00 | B9: Продленка Коновалова Евгения
A10: 16.00 -17.00 | B10: Творческая мастерская (Силосьева Алла) | C10: Творческая мастерская (Цуркан Юлия) | D10: Творческая мастерская (Аношко Лиана)
A13: Тьютор | B13: Тьютор Рассолова Екатерина
A14: Время | B14: Понедельник | C14: Вторник | D14: Среда | E14: Четверг | F14: Пятница
A15: 8.45-9.00 | B15: Сонастройка Абдуллаева | C15: Сонастройка Коновалова | D15: Сонастройка Абдуллаева | E15: Сонастройка Абдуллаева | F15: Сонастройка Коновалова
A16: 9.00-9.45 | B16: Русский язык Абдуллаева | C16: Окружающий мир Пашкова | D16: Русский язык Абдуллаева | E16: Технология Бондарь | F16: Математика Пашкова
A17: 9.55-10.40 | B17: Английский язык Малкова | C17: Литературное чтение Абдуллаева | D17: Английский язык Малкова | E17: Английский язык Малкова | F17: Окружающий мир Пашкова
A18: 10.50-11.35 | B18: Математика Пашкова | C18: Тьюторский час Рассолова | D18: Математика Пашкова | E18: Литературное чтение Абдуллаева | F18: Русский язык Абдуллаева
A19: 11.45-12.30 | B19: Музыка Карпова
A20: 12.30-15.00 | B20: ОБЕД
A21: 15.00-16.00 | B21: Продленка Коновалова Евгения
A22: 16.00 -17.00 | B22: Творческая мастерская (Силосьева Алла) | C22: Творческая мастерская (Цуркан Юлия) | D22: Творческая мастерская (Аношко Лиана)

Sheet 3А
A1: Тьютор | B1: Силосьева Алла
A2: Время | B2: Понедельник | C2: Вторник | D2: Среда | E2: Четверг | F2: Пятница | P2: 45929 | R2: 45930 | T2: 45938 | V2: 45939 | X2: 45989
A3: 8.45-9.00 | B3: Сонастройка Силосьева | C3: Сонастройка Силосьева Алла | D3: Сонастройка Силосьева | E3: Сонастройка Козлова | F3: Сонастройка Силосьева Алла | P3: Сонастройка | R3: Сонастройка | T3: Сонастройка | V3: Сонастройка | X3: Сонастройка
A4: 9.00-9.45 | B4: Математика Савина | C4: Литература Козлова | D4: Окружающий мир Савина | E4: Математика Савина | F4: Окружающий мир Савина | P4: Русский язык | R4: Литературное чтение | T4: Математика Савина | V4: Математика | X4: Английский язык
A5: 9.55-10.40 | B5: Английский язык Ерохина | C5: Математика Савина | D5: Литература Козлова | E5: Русский язык Козлова | F5: Русский язык Козлова | P5: Английский язык | R5: Математика | T5: Русский язык Козлова | V5: Русский язык | X5: Русский язык
A6: 10.50-11.35 | B6: Русский язык Козлова | C6: Английский язык Ерохина | D6: Тьюторский час Силосьева | E6: Физкультура Карабанова | F6: ИЗО Бондарь | P6: Математика | R6: Физкультура | X6: ИЗО
A7: 11.45-12.30 | F7: Английский язык Ерохина
A8: 12.30-15.00 | B8: ОБЕД
A9: 15.00-16.00 | B9: Продленка Аношко Лиана
A10: 16.00-17.00 | B10: Творческая мастерская Цуркан Юлия | C10: Творческая мастерская Силосьева Алла | D10: Творческая мастерская Цуркан Юлия
A13: Тьютор | B13: Силосьева Алла | I13: 46059
A14: Время | B14: Понедельник | C14: Вторник | D14: Среда | E14: Четверг | F14: Пятница | I14: Сонастройка
A15: 8.45-9.00 | B15: Сонастройка Силосьева | C15: Сонастройка Силосьева Алла | D15: Сонастройка Силосьева | E15: Сонастройка Козлова | F15: Сонастройка Силосьева Алла | I15: Окружающий мир
A16: 9.00-9.45 | B16: Математика Савина | C16: Литература Козлова | D16: Окружающий мир Савина | E16: Математика Савина | F16: Окружающий мир Савина | I16: Русский язык
A17: 9.55-10.40 | B17: Английский язык Ерохина | C17: Математика Савина | D17: Литература Козлова | E17: Русский язык Козлова | F17: Русский язык Козлова | I17: ИЗО
A18: 10.50-11.35 | B18: Русский язык Козлова | C18: Музыка Тронина | D18: Тьюторский час Силосьева | E18: Английский язык Ерохина | F18: ИЗО Бондарь
A19: 11.45-12.30 | F19: Английский язык Ерохина
A20: 12.30-15.00 | B20: ОБЕД
A21: 15.00-16.00 | B21: Продленка Аношко Лиана
A22: 16.00-17.00 | B22: Творческая мастерская Цуркан Юлия | C22: Творческая мастерская Силосьева Алла | D22: Творческая мастерская Цуркан Юлия

Sheet 3Б
A1: Тьютор | B1: Лиана Аношко
A2: Время | B2: Понедельник | C2: Вторник | D2: Среда | E2: Четверг | F2: Пятница | I2: 45940 | K2: 46014 | M2: 46015
A3: 11.30-11.45 | B3: Сонастройка Лиана Аношко | C3: Сонастройка Лиана Аношко | D3: Сонастройка Лиана Аношко | E3: Сонастройка Лиана Аношко | F3: Сонастройка Лиана Аношко | I3: Сонастройка | K3: Сонастройка | M3: Сонастройка
A4: 11.45-12.30 | B4: тьюторский час Аношко | C4: Литература Козлова | D4: Английский язык Ерохина | E4: Физкультура Карабанова | F4: Русский язык Козлова | I4: Русский язык | K4: Литература | M4: Английский язык
A5: 12.40-13.25 | B5: Русский язык Козлова | C5: Технология Бондарь | D5: Литература Козлова | E5: Русский язык Козлова | F5: Английский язык Ерохина | I5: Математика | K5: ИЗО | M5: Литература
A6: 13.35-14.20 | B6: Математика Савина | C6: Математика Савина | D6: Окружающий мир Савина | E6: Английский язык Ерохина | F6: Математика Савина | K6: Окружающий мир | M6: Математика
A7: 14.30-15.15 | B7: Окружающий мир Савина
A8: 14.20/15.15- 15.00/16.00 | B8: ОБЕД
A9: 15.00-16.00 | C9: продленка Аношко | D9: продленка Аношко | E9: продленка Аношко | F9: продленка Аношко
A10: 16.00-17.00 | B10: Творческая мастерская (Силосьева Алла) | C10: Творческая мастерская (Цуркан Юлия) | D10: Творческая мастерская (Аношко Лиана)
A13: Тьютор | B13: Лиана Аношко
A14: Время | B14: Понедельник | C14: Вторник | D14: Среда | E14: Четверг | F14: Пятница
A15: 11.30-11.45 | B15: Сонастройка Лиана Аношко | C15: Сонастройка Лиана Аношко | D15: Сонастройка Лиана Аношко | E15: Сонастройка Лиана Аношко | F15: Сонастройка Лиана Аношко
A16: 11.45-12.30 | B16: Музыка Карпова | C16: Литература Козлова | D16: Английский язык Ерохина | E16: тьюторский час Аношко | F16: Русский язык Козлова
A17: 12.40-13.25 | B17: Русский язык Козлова | C17: Технология Бондарь | D17: Литература Козлова | E17: Русский язык Козлова | F17: Английский язык Ерохина
A18: 13.35-14.20 | B18: Математика Савина | C18: Математика Савина | D18: Окружающий мир Савина | E18: Английский язык Ерохина | F18: Математика Савина
A19: 14.30-15.15 | B19: Окружающий мир Савина
A20: 14.20/15.15- 15.00/16.00 | B20: ОБЕД
A21: 15.00-16.00 | C21: продленка Аношко | D21: продленка Аношко | E21: продленка Аношко | F21: продленка Аношко
A22: 16.00-17.00 | B22: Творческая мастерская (Силосьева Алла) | C22: Творческая мастерская (Цуркан Юлия) | D22: Творческая мастерская (Аношко Лиана)
A25: Тьютор | B25: Лиана Аношко
A26: Время | B26: Понедельник | C26: Вторник | D26: Среда | E26: Четверг | F26: Пятница
A27: 11.30-11.45 | B27: Сонастройка Лиана Аношко | C27: Сонастройка Лиана Аношко | D27: Сонастройка Лиана Аношко | E27: Сонастройка Лиана Аношко | F27: Сонастройка Лиана Аношко
A28: 11.45-12.30 | B28: тьюторский час Аношко | C28: Литература Козлова | D28: Английский язык Ерохина | E28: Окружающий мир Савина | F28: Русский язык Козлова
A29: 12.40-13.25 | B29: Русский язык Козлова | C29: Технология Бондарь | D29: Литература Козлова | E29: Русский язык Козлова | F29: Английский язык Ерохина
A30: 13.35-14.20 | B30: Математика Савина | C30: Музыка Тронина | D30: Окружающий мир Савина | E30: Английский язык Ерохина | F30: Математика Савина
A31: 14.30-15.15 | B31: Окружающий мир Савина
A32: 14.20/15.15- 15.00/16.00 | B32: ОБЕД
A33: 15.00-16.00 | C33: продленка Аношко | D33: продленка Аношко | E33: продленка Аношко | F33: продленка Аношко
A34: 16.00-17.00 | B34: Творческая мастерская (Силосьева Алла) | C34: Творческая мастерская (Цуркан Юлия) | D34: Творческая мастерская (Аношко Лиана)

Sheet 3В
A1: Тьютор | B1: Лиана Аношко
A2: Время | B2: Понедельник | C2: Вторник | D2: Среда | E2: Четверг | F2: Пятница | I2: 45924 | K2: 45926 | M2: Сонастройка Лиана Аношко | O2: 45929 | Q2: 45939 | S2: 46015 | U2: 46017 | W2: 46015
A3: 8.45-9.00 | B3: Сонастройка Лиана Аношко | C3: Сонастройка Лиана Аношко | D3: Сонастройка Лиана Аношко | E3: Сонастройка Лиана Аношко | F3: Сонастройка Лиана Аношко | I3: Сонастройка | K3: Сонастройка | M3: Математика Чеченкова | O3: Сонастройка | Q3: Сонастройка | S3: Сонастройка | U3: Сонастройка | W3: Сонастройка
A4: 9.00-9.45 | B4: Математика Чеченкова | C4: Музыка Тронина | D4: Математика Чеченкова | E4: Литература Абдуллаева | F4: Русский язык Абдуллаева | I4: Математика | K4: Русский язык | M4: Русский язык Конохов | O4: Математика | Q4: Литература | S4: Окружающий мир | U4: Русский язык | W4: Окружающий мир
A5: 9.55-10.40 | B5: Тьюторский час Аношко | C5: Окружающий мир Чеченкова | D5: Английский язык Ерохина | E5: Английский язык Ерохина | F5: Окружающий мир Чеченкова | I5: Английский язык | K5: Окружающий мир | M5: Английский язык Ерохина | O5: Тьюторский час | Q5: Математика | S5: Английский язык | U5: Математика | W5: Русский язык
A6: 10.50-11.35 | B6: Русский язык Абдуллаева | C6: Литература Абдуллаева | D6: Русский язык Абдуллаева | E6: Математика Чеченкова | F6: Английский язык Ерохина | I6: Эмоциональный интеллект | K6: Русский язык | O6: Русский язык | S6: Русский язык | U6: Английский язык
A7: 11.45-12.30 | C7: Технология Бондарь
A8: 12.30-15.00 | B8: ОБЕД
A9: 15.00-16.00 | B9: Продленка Аношко Лиана
A10: 16.00-17.00 | B10: Творческая мастерская (Силосьева Алла) | C10: Творческая мастерская (Цуркан Юлия) | D10: Творческая мастерская (Аношко Лиана)

Sheet 4А
A1: Тьютор | B1: Цуркан Юлия
A2: Время | B2: Понедельник | C2: Вторник | D2: Среда | E2: Четверг | F2: Пятница | H2: 45989
A3: 8.45-9.00 | B3: Сонастройка Цуркан Юлия | C3: Сонастройка Чеченкова | D3: Сонастройка Цуркан Юлия | E3: Сонастройка Чеченкова | F3: Сонастройка Цуркан Юлия | H3: Сонастройка
A4: 9.00-9.45 | B4: тьюторский час Цуркан | C4: Математика Чеченкова | D4: Английский язык Малкова | E4: Английский язык Малкова | F4: Английский язык Малкова | H4: ИЗО
A5: 9.55-10.40 | B5: Окружающий мир Чеченкова | C5: Музыка Тронина | D5: Русский язык Петрова | E5: Математика Чеченкова | F5: Технология Бондарь | H5: Английский язык
A6: 10.50-11.35 | B6: Математика Чеченкова | C6: Русский язык Петрова | D6: Окружающий мир Чеченкова | F6: Русский язык Петрова | H6: Русский язык
A7: 11.45-12.30 | B7: Литература Петрова | F7: Литература Петрова | H7: Литература
A8: 12.30-15.00 | B8: ОБЕД
A9: 15.00-16.00 | B9: Продленка Цуркан Юлия
A10: 16.00-17.00 | B10: Творческая мастерская (Силосьева Алла) | C10: Творческая мастерская (Цуркан Юлия) | D10: Творческая мастерская (Аношко Лиана)

Sheet 4Б
A1: Тьютор | B1: Цуркан Юлия
A2: Время | B2: Понедельник | C2: Вторник | D2: Среда | E2: Четверг | F2: Пятница | P2: 45929 | R2: 45996 | T2: 46007 | V2: 46017 | X2: 46008
A3: 11.30-11.45 | B3: Сонастройка Цуркан Юлия | C3: Сонастройка Цуркан Юлия | D3: Сонастройка Цуркан Юлия | E3: Сонастройка Цуркан Юлия | F3: Сонастройка Цуркан Юлия | P3: Сонастройка | R3: Сонастройка | T3: Сонастройка | V3: Сонастройка | X3: Сонастройка
A4: 11.45-12.30 | B4: Технология Бондарь | C4: Математика Пашкова | D4: Окружающий мир Пашкова | E4: Математика Пашкова | F4: Окружающий мир Пашкова | P4: ИЗО | R4: Окружающий мир | T4: Окружающий мир | V4: Математика | X4: Окружающий мир
